<sdf version='1.4'>
  <world name='default'>
    <light name='sun' type='directional'>
      <cast_shadows>1</cast_shadows>
      <pose>0 0 10 0 -0 0</pose>
      <diffuse>0.8 0.8 0.8 1</diffuse>
      <specular>0.2 0.2 0.2 1</specular>
      <attenuation>
        <range>1000</range>
        <constant>0.9</constant>
        <linear>0.01</linear>
        <quadratic>0.001</quadratic>
      </attenuation>
      <direction>-0.5 0.1 -0.9</direction>
    </light>
    <model name='ground_plane'>
      <static>1</static>
      <link name='link'>
        <collision name='collision'>
          <geometry>
            <plane>
              <normal>0 0 1</normal>
              <size>100 100</size>
            </plane>
          </geometry>
          <surface>
            <friction>
              <ode>
                <mu>100</mu>
                <mu2>50</mu2>
              </ode>
            </friction>
            <bounce/>
            <contact>
              <ode/>
            </contact>
          </surface>
          <max_contacts>10</max_contacts>
        </collision>
        <visual name='visual'>
          <cast_shadows>0</cast_shadows>
          <geometry>
            <plane>
              <normal>0 0 1</normal>
              <size>100 100</size>
            </plane>
          </geometry>
          <material>
            <script>
              <uri>file://media/materials/scripts/gazebo.material</uri>
              <name>Gazebo/Grey</name>
            </script>
          </material>
        </visual>
        <velocity_decay>
          <linear>0</linear>
          <angular>0</angular>
        </velocity_decay>
        <self_collide>0</self_collide>
        <kinematic>0</kinematic>
        <gravity>1</gravity>
      </link>
    </model>
    <physics type='ode'>
      <max_step_size>0.001</max_step_size>
      <real_time_factor>1</real_time_factor>
      <real_time_update_rate>1000</real_time_update_rate>
      <gravity>0 0 -9.8</gravity>
    </physics>
    <scene>
      <ambient>0.4 0.4 0.4 1</ambient>
      <background>0.7 0.7 0.7 1</background>
      <shadows>1</shadows>
    </scene>
    <spherical_coordinates>
      <surface_model>EARTH_WGS84</surface_model>
      <latitude_deg>0</latitude_deg>
      <longitude_deg>0</longitude_deg>
      <elevation>0</elevation>
      <heading_deg>0</heading_deg>
    </spherical_coordinates>
    <model name='iRobot'>
      <link name='base_link'>
        <pose>0 0 0 0 -0 0</pose>
        <inertial>
          <pose>-9.99689e-06 0 2.05936e-06 0 -0 0</pose>
          <mass>10.0031</mass>
          <inertia>
            <ixx>0.425046</ixx>
            <ixy>0</ixy>
            <ixz>4.99979e-06</ixz>
            <iyy>0.425016</iyy>
            <iyz>-4.08016e-18</iyz>
            <izz>0.850052</izz>
          </inertia>
        </inertial>
        <collision name='base_link_collision_camera_link'>
          <pose>0 0 0.1 0 -0 0</pose>
          <geometry>
            <box>
              <size>0.02 0.08 0.05</size>
            </box>
          </geometry>
          <surface>
            <contact>
              <ode/>
            </contact>
            <friction>
              <ode/>
            </friction>
            <bounce/>
          </surface>
          <max_contacts>10</max_contacts>
        </collision>
        <collision name='base_link_collision_chassis'>
          <pose>0 0 0 0 -0 0</pose>
          <geometry>
            <cylinder>
              <length>0.08</length>
              <radius>0.17</radius>
            </cylinder>
          </geometry>
          <surface>
            <contact>
              <ode/>
            </contact>
            <friction>
              <ode/>
            </friction>
            <bounce/>
          </surface>
          <max_contacts>10</max_contacts>
        </collision>
        <collision name='base_link_collision_hokuyo_laser_link'>
          <pose>0 0 0.06 0 -0 0</pose>
          <geometry>
            <cylinder>
              <length>0.04</length>
              <radius>0.045</radius>
            </cylinder>
          </geometry>
          <surface>
            <contact>
              <ode/>
            </contact>
            <friction>
              <ode/>
            </friction>
            <bounce/>
          </surface>
          <max_contacts>10</max_contacts>
        </collision>
        <collision name='base_link_collision_imu_sensor_link'>
          <pose>-0.1 0 0.05 0 -0 0</pose>
          <geometry>
            <box>
              <size>0.02 0.02 0.02</size>
            </box>
          </geometry>
          <surface>
            <contact>
              <ode/>
            </contact>
            <friction>
              <ode/>
            </friction>
            <bounce/>
          </surface>
          <max_contacts>10</max_contacts>
        </collision>
        <collision name='base_link_collision_left_axis'>
          <pose>0 0.14 -0.02 -1.5708 0 0</pose>
          <geometry>
            <cylinder>
              <length>0.02</length>
              <radius>0.0025</radius>
            </cylinder>
          </geometry>
          <max_contacts>10</max_contacts>
          <surface>
            <bounce/>
            <friction>
              <ode/>
            </friction>
            <contact>
              <ode/>
            </contact>
          </surface>
        </collision>
        <collision name='base_link_collision_right_axis'>
          <pose>0 -0.14 -0.02 -1.5708 0 0</pose>
          <geometry>
            <cylinder>
              <length>0.02</length>
              <radius>0.0025</radius>
            </cylinder>
          </geometry>
          <max_contacts>10</max_contacts>
          <surface>
            <bounce/>
            <friction>
              <ode/>
            </friction>
            <contact>
              <ode/>
            </contact>
          </surface>
        </collision>
        <visual name='base_link_visual_camera_link'>
          <pose>0 0 0.1 0 -0 0</pose>
          <geometry>
            <box>
              <size>0.02 0.08 0.05</size>
            </box>
          </geometry>
        </visual>
        <visual name='base_link_visual_chassis'>
          <pose>0 0 0 0 -0 0</pose>
          <geometry>
            <cylinder>
              <length>0.08</length>
              <radius>0.17</radius>
            </cylinder>
          </geometry>
          <material>
            <script>
              <name>Gazebo/Yellow</name>
              <uri>__default__</uri>
            </script>
          </material>
        </visual>
        <visual name='base_link_visual_hokuyo_laser_link'>
          <pose>0 0 0.06 0 -0 0</pose>
          <geometry>
            <cylinder>
              <length>0.04</length>
              <radius>0.045</radius>
            </cylinder>
          </geometry>
        </visual>
        <visual name='base_link_visual_imu_sensor_link'>
          <pose>-0.1 0 0.05 0 -0 0</pose>
          <geometry>
            <box>
              <size>0.02 0.02 0.02</size>
            </box>
          </geometry>
        </visual>
        <visual name='base_link_visual_left_axis'>
          <pose>0 0.14 -0.02 -1.5708 0 0</pose>
          <geometry>
            <cylinder>
              <length>0.02</length>
              <radius>0.0025</radius>
            </cylinder>
          </geometry>
        </visual>
        <visual name='base_link_visual_right_axis'>
          <pose>0 -0.14 -0.02 -1.5708 0 0</pose>
          <geometry>
            <cylinder>
              <length>0.02</length>
              <radius>0.0025</radius>
            </cylinder>
          </geometry>
        </visual>
        <velocity_decay>
          <linear>0</linear>
          <angular>0</angular>
        </velocity_decay>
        <velocity_decay>
          <linear>0</linear>
          <angular>0</angular>
        </velocity_decay>
        <velocity_decay>
          <linear>0</linear>
          <angular>0</angular>
        </velocity_decay>
        <sensor name='camera' type='camera'>
          <update_rate>30</update_rate>
          <camera name='head'>
            <horizontal_fov>1.39626</horizontal_fov>
            <image>
              <width>800</width>
              <height>600</height>
              <format>R8G8B8</format>
            </image>
            <clip>
              <near>0.02</near>
              <far>300</far>
            </clip>
            <noise>
              <type>gaussian</type>
              <mean>0</mean>
              <stddev>0.007</stddev>
            </noise>
          </camera>
          <plugin name='camera_controller' filename='libgazebo_ros_camera.so'>
            <alwaysOn>true</alwaysOn>
            <updateRate>0.0</updateRate>
            <cameraName>iRobot/camera</cameraName>
            <imageTopicName>image_raw</imageTopicName>
            <cameraInfoTopicName>camera_info</cameraInfoTopicName>
            <frameName>camera_link</frameName>
            <hackBaseline>0.07</hackBaseline>
            <distortionK1>0.0</distortionK1>
            <distortionK2>0.0</distortionK2>
            <distortionK3>0.0</distortionK3>
            <distortionT1>0.0</distortionT1>
            <distortionT2>0.0</distortionT2>
          </plugin>
          <pose>0 0 0.1 0 -0 0</pose>
        </sensor>
        <gravity>1</gravity>
        <velocity_decay>
          <linear>0</linear>
          <angular>0</angular>
        </velocity_decay>
        <gravity>1</gravity>
        <sensor name='head_hokuyo_sensor' type='ray'>
          <visualize>0</visualize>
          <update_rate>40</update_rate>
          <ray>
            <scan>
              <horizontal>
                <samples>360</samples>
                <resolution>1</resolution>
                <min_angle>-3.14159</min_angle>
                <max_angle>3.14159</max_angle>
              </horizontal>
            </scan>
            <range>
              <min>0.06</min>
              <max>40</max>
              <resolution>0.025</resolution>
            </range>
            <noise>
              <type>gaussian</type>
              <mean>0</mean>
              <stddev>0</stddev>
            </noise>
          </ray>
          <plugin name='gazebo_ros_head_hokuyo_controller' filename='libgazebo_ros_laser.so'>
            <robotNamespace/>
            <topicName>laser_scan</topicName>
            <frameName>hokuyo_laser_link</frameName>
          </plugin>
          <pose>0 0 0.06 0 -0 0</pose>
        </sensor>
        <gravity>1</gravity>
        <velocity_decay>
          <linear>0</linear>
          <angular>0</angular>
        </velocity_decay>
        <self_collide>0</self_collide>
        <gravity>1</gravity>
        <sensor name='imu_sensor' type='imu'>
          <always_on>1</always_on>
          <update_rate>1000</update_rate>
          <visualize>1</visualize>
          <topic>__default_topic__</topic>
          <plugin name='imu_plugin' filename='libgazebo_ros_imu_sensor.so'>
            <topicName>imu_data</topicName>
            <bodyName>imu_sensor_link</bodyName>
            <updateRateHZ>10.0</updateRateHZ>
            <gaussianNoise>0.0</gaussianNoise>
            <xyzOffset>0 0 0</xyzOffset>
            <rpyOffset>0 0 0</rpyOffset>
          </plugin>
          <pose>-0.1 0 0.05 0 -0 0</pose>
        </sensor>
        <kinematic>0</kinematic>
      </link>
      <link name='left_wheel_link'>
        <pose>0 0.14 -0.02 0 -0 0</pose>
        <inertial>
          <pose>0 0.01 0 -1.5708 0 0</pose>
          <mass>0.5</mass>
          <inertia>
            <ixx>0.00375</ixx>
            <ixy>0</ixy>
            <ixz>0</ixz>
            <iyy>0.00375</iyy>
            <iyz>0</iyz>
            <izz>0.00125</izz>
          </inertia>
        </inertial>
        <collision name='left_wheel_link_collision'>
          <pose>0 0 0 -1.5708 0 0</pose>
          <geometry>
            <cylinder>
              <length>0.02</length>
              <radius>0.03</radius>
            </cylinder>
          </geometry>
          <max_contacts>1</max_contacts>
          <surface>
            <contact>
              <ode>
                <kp>1e+07</kp>
                <kd>1</kd>
                <min_depth>0.0001</min_depth>
              </ode>
            </contact>
            <friction>
              <ode>
                <mu>50</mu>
                <mu2>10</mu2>
                <fdir1>1 0 0</fdir1>
              </ode>
            </friction>
            <bounce/>
          </surface>
        </collision>
        <visual name='left_wheel_link_visual'>
          <pose>0 0 0 -1.5708 0 0</pose>
          <geometry>
            <cylinder>
              <length>0.02</length>
              <radius>0.03</radius>
            </cylinder>
          </geometry>
          <material>
            <script>
              <name>Gazebo/Grey</name>
              <uri>__default__</uri>
            </script>
          </material>
        </visual>
        <gravity>1</gravity>
        <velocity_decay>
          <linear>0</linear>
          <angular>0</angular>
        </velocity_decay>
        <self_collide>0</self_collide>
        <gravity>1</gravity>
        <kinematic>0</kinematic>
      </link>
      <joint name='left_wheel_rot_joint' type='revolute'>
        <child>left_wheel_link</child>
        <parent>base_link</parent>
        <axis>
          <xyz>0 1 0</xyz>
          <limit>
            <lower>-1e+16</lower>
            <upper>1e+16</upper>
          </limit>
          <dynamics/>
        </axis>
      </joint>
      <link name='right_wheel_link'>
        <pose>0 -0.14 -0.02 0 -0 0</pose>
        <inertial>
          <pose>0 0.01 0 -1.5708 0 0</pose>
          <mass>0.5</mass>
          <inertia>
            <ixx>0.00375</ixx>
            <ixy>0</ixy>
            <ixz>0</ixz>
            <iyy>0.00375</iyy>
            <iyz>0</iyz>
            <izz>0.00125</izz>
          </inertia>
        </inertial>
        <collision name='right_wheel_link_collision'>
          <pose>0 0 0 -1.5708 0 0</pose>
          <geometry>
            <cylinder>
              <length>0.02</length>
              <radius>0.03</radius>
            </cylinder>
          </geometry>
          <max_contacts>1</max_contacts>
          <surface>
            <contact>
              <ode>
                <kp>1e+07</kp>
                <kd>1</kd>
                <min_depth>0.0001</min_depth>
              </ode>
            </contact>
            <friction>
              <ode>
                <mu>50</mu>
                <mu2>10</mu2>
                <fdir1>1 0 0</fdir1>
              </ode>
            </friction>
            <bounce/>
          </surface>
        </collision>
        <visual name='right_wheel_link_visual'>
          <pose>0 0 0 -1.5708 0 0</pose>
          <geometry>
            <cylinder>
              <length>0.02</length>
              <radius>0.03</radius>
            </cylinder>
          </geometry>
          <material>
            <script>
              <name>Gazebo/Grey</name>
              <uri>__default__</uri>
            </script>
          </material>
        </visual>
        <gravity>1</gravity>
        <velocity_decay>
          <linear>0</linear>
          <angular>0</angular>
        </velocity_decay>
        <self_collide>0</self_collide>
        <gravity>1</gravity>
        <kinematic>0</kinematic>
      </link>
      <joint name='right_wheel_rot_joint' type='revolute'>
        <child>right_wheel_link</child>
        <parent>base_link</parent>
        <axis>
          <xyz>0 1 0</xyz>
          <limit>
            <lower>-1e+16</lower>
            <upper>1e+16</upper>
          </limit>
          <dynamics/>
        </axis>
      </joint>
      <link name='sphere1'>
        <pose>0.14 0 -0.04 0 -0 0</pose>
        <inertial>
          <pose>0 0 0 0 -0 0</pose>
          <mass>0.3</mass>
          <inertia>
            <ixx>0.0012</ixx>
            <ixy>0</ixy>
            <ixz>0</ixz>
            <iyy>0.0012</iyy>
            <iyz>0</iyz>
            <izz>0.0012</izz>
          </inertia>
        </inertial>
        <collision name='sphere1_collision'>
          <pose>0 0 0 0 -0 0</pose>
          <geometry>
            <sphere>
              <radius>0.01</radius>
            </sphere>
          </geometry>
          <max_contacts>1</max_contacts>
          <surface>
            <contact>
              <ode>
                <kp>1e+07</kp>
                <kd>1</kd>
                <min_depth>0.0001</min_depth>
              </ode>
            </contact>
            <friction>
              <ode>
                <mu>0</mu>
                <mu2>0</mu2>
                <fdir1>1 0 0</fdir1>
              </ode>
            </friction>
            <bounce/>
          </surface>
        </collision>
        <visual name='sphere1_visual'>
          <pose>0 0 0 0 -0 0</pose>
          <geometry>
            <sphere>
              <radius>0.01</radius>
            </sphere>
          </geometry>
          <material>
            <script>
              <name>Gazebo/Grey</name>
              <uri>__default__</uri>
            </script>
          </material>
        </visual>
        <gravity>1</gravity>
        <velocity_decay>
          <linear>0</linear>
          <angular>0</angular>
        </velocity_decay>
        <self_collide>0</self_collide>
        <gravity>1</gravity>
        <kinematic>0</kinematic>
      </link>
      <joint name='sphere_joint1' type='revolute'>
        <child>sphere1</child>
        <parent>base_link</parent>
        <axis>
          <xyz>0 0 1</xyz>
          <limit>
            <lower>0</lower>
            <upper>0</upper>
            <effort>100</effort>
            <velocity>100</velocity>
          </limit>
          <dynamics/>
        </axis>
      </joint>
      <link name='sphere2'>
        <pose>-0.14 0 -0.04 0 -0 0</pose>
        <inertial>
          <pose>0 0 0 0 -0 0</pose>
          <mass>0.3</mass>
          <inertia>
            <ixx>0.0012</ixx>
            <ixy>0</ixy>
            <ixz>0</ixz>
            <iyy>0.0012</iyy>
            <iyz>0</iyz>
            <izz>0.0012</izz>
          </inertia>
        </inertial>
        <collision name='sphere2_collision'>
          <pose>0 0 0 0 -0 0</pose>
          <geometry>
            <sphere>
              <radius>0.01</radius>
            </sphere>
          </geometry>
          <max_contacts>1</max_contacts>
          <surface>
            <contact>
              <ode>
                <kp>1e+07</kp>
                <kd>1</kd>
                <min_depth>0.0001</min_depth>
              </ode>
            </contact>
            <friction>
              <ode>
                <mu>0</mu>
                <mu2>0</mu2>
                <fdir1>1 0 0</fdir1>
              </ode>
            </friction>
            <bounce/>
          </surface>
        </collision>
        <visual name='sphere2_visual'>
          <pose>0 0 0 0 -0 0</pose>
          <geometry>
            <sphere>
              <radius>0.01</radius>
            </sphere>
          </geometry>
          <material>
            <script>
              <name>Gazebo/Grey</name>
              <uri>__default__</uri>
            </script>
          </material>
        </visual>
        <gravity>1</gravity>
        <velocity_decay>
          <linear>0</linear>
          <angular>0</angular>
        </velocity_decay>
        <self_collide>0</self_collide>
        <gravity>1</gravity>
        <kinematic>0</kinematic>
      </link>
      <joint name='sphere_joint2' type='revolute'>
        <child>sphere2</child>
        <parent>base_link</parent>
        <axis>
          <xyz>0 0 1</xyz>
          <limit>
            <lower>0</lower>
            <upper>0</upper>
            <effort>100</effort>
            <velocity>100</velocity>
          </limit>
          <dynamics/>
        </axis>
      </joint>
      <static>0</static>
      <plugin name='differential_drive_controller' filename='libgazebo_ros_diff_drive.so'>
        <rosDebugLevel>Debug</rosDebugLevel>
        <publishWheelTF>false</publishWheelTF>
        <publishWheelJointState>true</publishWheelJointState>
        <alwaysOn>true</alwaysOn>
        <leftJoint>left_wheel_rot_joint</leftJoint>
        <rightJoint>right_wheel_rot_joint</rightJoint>
        <wheelSeparation>0.28</wheelSeparation>
        <wheelDiameter>0.06</wheelDiameter>
        <torque>20</torque>
        <wheelAcceleration>1.8</wheelAcceleration>
        <commandTopic>cmd_vel</commandTopic>
        <odometryTopic>odom</odometryTopic>
        <odometryFrame>odom</odometryFrame>
        <odometrySource>encoder</odometrySource>
        <robotBaseFrame>base_link</robotBaseFrame>
        <updateRate>10.0</updateRate>
      </plugin>
      <plugin name='joint_state_publisher' filename='libgazebo_ros_joint_state_publisher.so'>
        <jointName>left_wheel_rot_joint, right_wheel_rot_joint</jointName>
        <updateRate>10.0</updateRate>
        <alwaysOn>true</alwaysOn>
      </plugin>
      <plugin name='imu_plugin' filename='libgazebo_ros_imu.so'>
        <bodyName>base_link</bodyName>
        <updateRate>100.0</updateRate>
        <topicName>imu_data</topicName>
        <serviceName>imu_service</serviceName>
        <gaussianNoise>0.1</gaussianNoise>
        <xyzOffset>0 0 0</xyzOffset>
        <rpyOffset>0 0 0</rpyOffset>
      </plugin>
      <pose>-1 -2 0 0 -0 0</pose>
    </model>
    <model name='iRobot_0'>
      <link name='base_link'>
        <pose>0 0 0 0 -0 0</pose>
        <inertial>
          <pose>-9.99689e-06 0 2.05936e-06 0 -0 0</pose>
          <mass>10.0031</mass>
          <inertia>
            <ixx>0.425046</ixx>
            <ixy>0</ixy>
            <ixz>4.99979e-06</ixz>
            <iyy>0.425016</iyy>
            <iyz>-4.08016e-18</iyz>
            <izz>0.850052</izz>
          </inertia>
        </inertial>
        <collision name='base_link_collision_camera_link'>
          <pose>0 0 0.1 0 -0 0</pose>
          <geometry>
            <box>
              <size>0.02 0.08 0.05</size>
            </box>
          </geometry>
          <surface>
            <contact>
              <ode/>
            </contact>
            <friction>
              <ode/>
            </friction>
            <bounce/>
          </surface>
          <max_contacts>10</max_contacts>
        </collision>
        <collision name='base_link_collision_chassis'>
          <pose>0 0 0 0 -0 0</pose>
          <geometry>
            <cylinder>
              <length>0.08</length>
              <radius>0.17</radius>
            </cylinder>
          </geometry>
          <surface>
            <contact>
              <ode/>
            </contact>
            <friction>
              <ode/>
            </friction>
            <bounce/>
          </surface>
          <max_contacts>10</max_contacts>
        </collision>
        <collision name='base_link_collision_hokuyo_laser_link'>
          <pose>0 0 0.06 0 -0 0</pose>
          <geometry>
            <cylinder>
              <length>0.04</length>
              <radius>0.045</radius>
            </cylinder>
          </geometry>
          <surface>
            <contact>
              <ode/>
            </contact>
            <friction>
              <ode/>
            </friction>
            <bounce/>
          </surface>
          <max_contacts>10</max_contacts>
        </collision>
        <collision name='base_link_collision_imu_sensor_link'>
          <pose>-0.1 0 0.05 0 -0 0</pose>
          <geometry>
            <box>
              <size>0.02 0.02 0.02</size>
            </box>
          </geometry>
          <surface>
            <contact>
              <ode/>
            </contact>
            <friction>
              <ode/>
            </friction>
            <bounce/>
          </surface>
          <max_contacts>10</max_contacts>
        </collision>
        <collision name='base_link_collision_left_axis'>
          <pose>0 0.14 -0.02 -1.5708 0 0</pose>
          <geometry>
            <cylinder>
              <length>0.02</length>
              <radius>0.0025</radius>
            </cylinder>
          </geometry>
          <max_contacts>10</max_contacts>
          <surface>
            <bounce/>
            <friction>
              <ode/>
            </friction>
            <contact>
              <ode/>
            </contact>
          </surface>
        </collision>
        <collision name='base_link_collision_right_axis'>
          <pose>0 -0.14 -0.02 -1.5708 0 0</pose>
          <geometry>
            <cylinder>
              <length>0.02</length>
              <radius>0.0025</radius>
            </cylinder>
          </geometry>
          <max_contacts>10</max_contacts>
          <surface>
            <bounce/>
            <friction>
              <ode/>
            </friction>
            <contact>
              <ode/>
            </contact>
          </surface>
        </collision>
        <visual name='base_link_visual_camera_link'>
          <pose>0 0 0.1 0 -0 0</pose>
          <geometry>
            <box>
              <size>0.02 0.08 0.05</size>
            </box>
          </geometry>
        </visual>
        <visual name='base_link_visual_chassis'>
          <pose>0 0 0 0 -0 0</pose>
          <geometry>
            <cylinder>
              <length>0.08</length>
              <radius>0.17</radius>
            </cylinder>
          </geometry>
          <material>
            <script>
              <name>Gazebo/Yellow</name>
              <uri>__default__</uri>
            </script>
          </material>
        </visual>
        <visual name='base_link_visual_hokuyo_laser_link'>
          <pose>0 0 0.06 0 -0 0</pose>
          <geometry>
            <cylinder>
              <length>0.04</length>
              <radius>0.045</radius>
            </cylinder>
          </geometry>
        </visual>
        <visual name='base_link_visual_imu_sensor_link'>
          <pose>-0.1 0 0.05 0 -0 0</pose>
          <geometry>
            <box>
              <size>0.02 0.02 0.02</size>
            </box>
          </geometry>
        </visual>
        <visual name='base_link_visual_left_axis'>
          <pose>0 0.14 -0.02 -1.5708 0 0</pose>
          <geometry>
            <cylinder>
              <length>0.02</length>
              <radius>0.0025</radius>
            </cylinder>
          </geometry>
        </visual>
        <visual name='base_link_visual_right_axis'>
          <pose>0 -0.14 -0.02 -1.5708 0 0</pose>
          <geometry>
            <cylinder>
              <length>0.02</length>
              <radius>0.0025</radius>
            </cylinder>
          </geometry>
        </visual>
        <velocity_decay>
          <linear>0</linear>
          <angular>0</angular>
        </velocity_decay>
        <velocity_decay>
          <linear>0</linear>
          <angular>0</angular>
        </velocity_decay>
        <velocity_decay>
          <linear>0</linear>
          <angular>0</angular>
        </velocity_decay>
        <sensor name='camera' type='camera'>
          <update_rate>30</update_rate>
          <camera name='head'>
            <horizontal_fov>1.39626</horizontal_fov>
            <image>
              <width>800</width>
              <height>600</height>
              <format>R8G8B8</format>
            </image>
            <clip>
              <near>0.02</near>
              <far>300</far>
            </clip>
            <noise>
              <type>gaussian</type>
              <mean>0</mean>
              <stddev>0.007</stddev>
            </noise>
          </camera>
          <plugin name='camera_controller' filename='libgazebo_ros_camera.so'>
            <alwaysOn>true</alwaysOn>
            <updateRate>0.0</updateRate>
            <cameraName>iRobot/camera</cameraName>
            <imageTopicName>image_raw</imageTopicName>
            <cameraInfoTopicName>camera_info</cameraInfoTopicName>
            <frameName>camera_link</frameName>
            <hackBaseline>0.07</hackBaseline>
            <distortionK1>0.0</distortionK1>
            <distortionK2>0.0</distortionK2>
            <distortionK3>0.0</distortionK3>
            <distortionT1>0.0</distortionT1>
            <distortionT2>0.0</distortionT2>
          </plugin>
          <pose>0 0 0.1 0 -0 0</pose>
        </sensor>
        <gravity>1</gravity>
        <velocity_decay>
          <linear>0</linear>
          <angular>0</angular>
        </velocity_decay>
        <gravity>1</gravity>
        <sensor name='head_hokuyo_sensor' type='ray'>
          <visualize>0</visualize>
          <update_rate>40</update_rate>
          <ray>
            <scan>
              <horizontal>
                <samples>360</samples>
                <resolution>1</resolution>
                <min_angle>-3.14159</min_angle>
                <max_angle>3.14159</max_angle>
              </horizontal>
            </scan>
            <range>
              <min>0.06</min>
              <max>40</max>
              <resolution>0.025</resolution>
            </range>
            <noise>
              <type>gaussian</type>
              <mean>0</mean>
              <stddev>0</stddev>
            </noise>
          </ray>
          <plugin name='gazebo_ros_head_hokuyo_controller' filename='libgazebo_ros_laser.so'>
            <robotNamespace/>
            <topicName>laser_scan</topicName>
            <frameName>hokuyo_laser_link</frameName>
          </plugin>
          <pose>0 0 0.06 0 -0 0</pose>
        </sensor>
        <gravity>1</gravity>
        <velocity_decay>
          <linear>0</linear>
          <angular>0</angular>
        </velocity_decay>
        <self_collide>0</self_collide>
        <gravity>1</gravity>
        <sensor name='imu_sensor' type='imu'>
          <always_on>1</always_on>
          <update_rate>1000</update_rate>
          <visualize>1</visualize>
          <topic>__default_topic__</topic>
          <plugin name='imu_plugin' filename='libgazebo_ros_imu_sensor.so'>
            <topicName>imu_data</topicName>
            <bodyName>imu_sensor_link</bodyName>
            <updateRateHZ>10.0</updateRateHZ>
            <gaussianNoise>0.0</gaussianNoise>
            <xyzOffset>0 0 0</xyzOffset>
            <rpyOffset>0 0 0</rpyOffset>
          </plugin>
          <pose>-0.1 0 0.05 0 -0 0</pose>
        </sensor>
        <kinematic>0</kinematic>
      </link>
      <link name='left_wheel_link'>
        <pose>0 0.14 -0.02 0 -0 0</pose>
        <inertial>
          <pose>0 0.01 0 -1.5708 0 0</pose>
          <mass>0.5</mass>
          <inertia>
            <ixx>0.00375</ixx>
            <ixy>0</ixy>
            <ixz>0</ixz>
            <iyy>0.00375</iyy>
            <iyz>0</iyz>
            <izz>0.00125</izz>
          </inertia>
        </inertial>
        <collision name='left_wheel_link_collision'>
          <pose>0 0 0 -1.5708 0 0</pose>
          <geometry>
            <cylinder>
              <length>0.02</length>
              <radius>0.03</radius>
            </cylinder>
          </geometry>
          <max_contacts>1</max_contacts>
          <surface>
            <contact>
              <ode>
                <kp>1e+07</kp>
                <kd>1</kd>
                <min_depth>0.0001</min_depth>
              </ode>
            </contact>
            <friction>
              <ode>
                <mu>50</mu>
                <mu2>10</mu2>
                <fdir1>1 0 0</fdir1>
              </ode>
            </friction>
            <bounce/>
          </surface>
        </collision>
        <visual name='left_wheel_link_visual'>
          <pose>0 0 0 -1.5708 0 0</pose>
          <geometry>
            <cylinder>
              <length>0.02</length>
              <radius>0.03</radius>
            </cylinder>
          </geometry>
          <material>
            <script>
              <name>Gazebo/Grey</name>
              <uri>__default__</uri>
            </script>
          </material>
        </visual>
        <gravity>1</gravity>
        <velocity_decay>
          <linear>0</linear>
          <angular>0</angular>
        </velocity_decay>
        <self_collide>0</self_collide>
        <gravity>1</gravity>
        <kinematic>0</kinematic>
      </link>
      <joint name='left_wheel_rot_joint' type='revolute'>
        <child>left_wheel_link</child>
        <parent>base_link</parent>
        <axis>
          <xyz>0 1 0</xyz>
          <limit>
            <lower>-1e+16</lower>
            <upper>1e+16</upper>
          </limit>
          <dynamics/>
        </axis>
      </joint>
      <link name='right_wheel_link'>
        <pose>0 -0.14 -0.02 0 -0 0</pose>
        <inertial>
          <pose>0 0.01 0 -1.5708 0 0</pose>
          <mass>0.5</mass>
          <inertia>
            <ixx>0.00375</ixx>
            <ixy>0</ixy>
            <ixz>0</ixz>
            <iyy>0.00375</iyy>
            <iyz>0</iyz>
            <izz>0.00125</izz>
          </inertia>
        </inertial>
        <collision name='right_wheel_link_collision'>
          <pose>0 0 0 -1.5708 0 0</pose>
          <geometry>
            <cylinder>
              <length>0.02</length>
              <radius>0.03</radius>
            </cylinder>
          </geometry>
          <max_contacts>1</max_contacts>
          <surface>
            <contact>
              <ode>
                <kp>1e+07</kp>
                <kd>1</kd>
                <min_depth>0.0001</min_depth>
              </ode>
            </contact>
            <friction>
              <ode>
                <mu>50</mu>
                <mu2>10</mu2>
                <fdir1>1 0 0</fdir1>
              </ode>
            </friction>
            <bounce/>
          </surface>
        </collision>
        <visual name='right_wheel_link_visual'>
          <pose>0 0 0 -1.5708 0 0</pose>
          <geometry>
            <cylinder>
              <length>0.02</length>
              <radius>0.03</radius>
            </cylinder>
          </geometry>
          <material>
            <script>
              <name>Gazebo/Grey</name>
              <uri>__default__</uri>
            </script>
          </material>
        </visual>
        <gravity>1</gravity>
        <velocity_decay>
          <linear>0</linear>
          <angular>0</angular>
        </velocity_decay>
        <self_collide>0</self_collide>
        <gravity>1</gravity>
        <kinematic>0</kinematic>
      </link>
      <joint name='right_wheel_rot_joint' type='revolute'>
        <child>right_wheel_link</child>
        <parent>base_link</parent>
        <axis>
          <xyz>0 1 0</xyz>
          <limit>
            <lower>-1e+16</lower>
            <upper>1e+16</upper>
          </limit>
          <dynamics/>
        </axis>
      </joint>
      <link name='sphere1'>
        <pose>0.14 0 -0.04 0 -0 0</pose>
        <inertial>
          <pose>0 0 0 0 -0 0</pose>
          <mass>0.3</mass>
          <inertia>
            <ixx>0.0012</ixx>
            <ixy>0</ixy>
            <ixz>0</ixz>
            <iyy>0.0012</iyy>
            <iyz>0</iyz>
            <izz>0.0012</izz>
          </inertia>
        </inertial>
        <collision name='sphere1_collision'>
          <pose>0 0 0 0 -0 0</pose>
          <geometry>
            <sphere>
              <radius>0.01</radius>
            </sphere>
          </geometry>
          <max_contacts>1</max_contacts>
          <surface>
            <contact>
              <ode>
                <kp>1e+07</kp>
                <kd>1</kd>
                <min_depth>0.0001</min_depth>
              </ode>
            </contact>
            <friction>
              <ode>
                <mu>0</mu>
                <mu2>0</mu2>
                <fdir1>1 0 0</fdir1>
              </ode>
            </friction>
            <bounce/>
          </surface>
        </collision>
        <visual name='sphere1_visual'>
          <pose>0 0 0 0 -0 0</pose>
          <geometry>
            <sphere>
              <radius>0.01</radius>
            </sphere>
          </geometry>
          <material>
            <script>
              <name>Gazebo/Grey</name>
              <uri>__default__</uri>
            </script>
          </material>
        </visual>
        <gravity>1</gravity>
        <velocity_decay>
          <linear>0</linear>
          <angular>0</angular>
        </velocity_decay>
        <self_collide>0</self_collide>
        <gravity>1</gravity>
        <kinematic>0</kinematic>
      </link>
      <joint name='sphere_joint1' type='revolute'>
        <child>sphere1</child>
        <parent>base_link</parent>
        <axis>
          <xyz>0 0 1</xyz>
          <limit>
            <lower>0</lower>
            <upper>0</upper>
            <effort>100</effort>
            <velocity>100</velocity>
          </limit>
          <dynamics/>
        </axis>
      </joint>
      <link name='sphere2'>
        <pose>-0.14 0 -0.04 0 -0 0</pose>
        <inertial>
          <pose>0 0 0 0 -0 0</pose>
          <mass>0.3</mass>
          <inertia>
            <ixx>0.0012</ixx>
            <ixy>0</ixy>
            <ixz>0</ixz>
            <iyy>0.0012</iyy>
            <iyz>0</iyz>
            <izz>0.0012</izz>
          </inertia>
        </inertial>
        <collision name='sphere2_collision'>
          <pose>0 0 0 0 -0 0</pose>
          <geometry>
            <sphere>
              <radius>0.01</radius>
            </sphere>
          </geometry>
          <max_contacts>1</max_contacts>
          <surface>
            <contact>
              <ode>
                <kp>1e+07</kp>
                <kd>1</kd>
                <min_depth>0.0001</min_depth>
              </ode>
            </contact>
            <friction>
              <ode>
                <mu>0</mu>
                <mu2>0</mu2>
                <fdir1>1 0 0</fdir1>
              </ode>
            </friction>
            <bounce/>
          </surface>
        </collision>
        <visual name='sphere2_visual'>
          <pose>0 0 0 0 -0 0</pose>
          <geometry>
            <sphere>
              <radius>0.01</radius>
            </sphere>
          </geometry>
          <material>
            <script>
              <name>Gazebo/Grey</name>
              <uri>__default__</uri>
            </script>
          </material>
        </visual>
        <gravity>1</gravity>
        <velocity_decay>
          <linear>0</linear>
          <angular>0</angular>
        </velocity_decay>
        <self_collide>0</self_collide>
        <gravity>1</gravity>
        <kinematic>0</kinematic>
      </link>
      <joint name='sphere_joint2' type='revolute'>
        <child>sphere2</child>
        <parent>base_link</parent>
        <axis>
          <xyz>0 0 1</xyz>
          <limit>
            <lower>0</lower>
            <upper>0</upper>
            <effort>100</effort>
            <velocity>100</velocity>
          </limit>
          <dynamics/>
        </axis>
      </joint>
      <static>0</static>
      <plugin name='differential_drive_controller' filename='libgazebo_ros_diff_drive.so'>
        <rosDebugLevel>Debug</rosDebugLevel>
        <publishWheelTF>false</publishWheelTF>
        <publishWheelJointState>true</publishWheelJointState>
        <alwaysOn>true</alwaysOn>
        <leftJoint>left_wheel_rot_joint</leftJoint>
        <rightJoint>right_wheel_rot_joint</rightJoint>
        <wheelSeparation>0.28</wheelSeparation>
        <wheelDiameter>0.06</wheelDiameter>
        <torque>20</torque>
        <wheelAcceleration>1.8</wheelAcceleration>
        <commandTopic>cmd_vel</commandTopic>
        <odometryTopic>odom</odometryTopic>
        <odometryFrame>odom</odometryFrame>
        <odometrySource>encoder</odometrySource>
        <robotBaseFrame>base_link</robotBaseFrame>
        <updateRate>10.0</updateRate>
      </plugin>
      <plugin name='joint_state_publisher' filename='libgazebo_ros_joint_state_publisher.so'>
        <jointName>left_wheel_rot_joint, right_wheel_rot_joint</jointName>
        <updateRate>10.0</updateRate>
        <alwaysOn>true</alwaysOn>
      </plugin>
      <plugin name='imu_plugin' filename='libgazebo_ros_imu.so'>
        <bodyName>base_link</bodyName>
        <updateRate>100.0</updateRate>
        <topicName>imu_data</topicName>
        <serviceName>imu_service</serviceName>
        <gaussianNoise>0.1</gaussianNoise>
        <xyzOffset>0 0 0</xyzOffset>
        <rpyOffset>0 0 0</rpyOffset>
      </plugin>
      <pose>0 -2 0 0 -0 0</pose>
    </model>
    <model name='iRobot_1'>
      <link name='base_link'>
        <pose>0 0 0 0 -0 0</pose>
        <inertial>
          <pose>-9.99689e-06 0 2.05936e-06 0 -0 0</pose>
          <mass>10.0031</mass>
          <inertia>
            <ixx>0.425046</ixx>
            <ixy>0</ixy>
            <ixz>4.99979e-06</ixz>
            <iyy>0.425016</iyy>
            <iyz>-4.08016e-18</iyz>
            <izz>0.850052</izz>
          </inertia>
        </inertial>
        <collision name='base_link_collision_camera_link'>
          <pose>0 0 0.1 0 -0 0</pose>
          <geometry>
            <box>
              <size>0.02 0.08 0.05</size>
            </box>
          </geometry>
          <surface>
            <contact>
              <ode/>
            </contact>
            <friction>
              <ode/>
            </friction>
            <bounce/>
          </surface>
          <max_contacts>10</max_contacts>
        </collision>
        <collision name='base_link_collision_chassis'>
          <pose>0 0 0 0 -0 0</pose>
          <geometry>
            <cylinder>
              <length>0.08</length>
              <radius>0.17</radius>
            </cylinder>
          </geometry>
          <surface>
            <contact>
              <ode/>
            </contact>
            <friction>
              <ode/>
            </friction>
            <bounce/>
          </surface>
          <max_contacts>10</max_contacts>
        </collision>
        <collision name='base_link_collision_hokuyo_laser_link'>
          <pose>0 0 0.06 0 -0 0</pose>
          <geometry>
            <cylinder>
              <length>0.04</length>
              <radius>0.045</radius>
            </cylinder>
          </geometry>
          <surface>
            <contact>
              <ode/>
            </contact>
            <friction>
              <ode/>
            </friction>
            <bounce/>
          </surface>
          <max_contacts>10</max_contacts>
        </collision>
        <collision name='base_link_collision_imu_sensor_link'>
          <pose>-0.1 0 0.05 0 -0 0</pose>
          <geometry>
            <box>
              <size>0.02 0.02 0.02</size>
            </box>
          </geometry>
          <surface>
            <contact>
              <ode/>
            </contact>
            <friction>
              <ode/>
            </friction>
            <bounce/>
          </surface>
          <max_contacts>10</max_contacts>
        </collision>
        <collision name='base_link_collision_left_axis'>
          <pose>0 0.14 -0.02 -1.5708 0 0</pose>
          <geometry>
            <cylinder>
              <length>0.02</length>
              <radius>0.0025</radius>
            </cylinder>
          </geometry>
          <max_contacts>10</max_contacts>
          <surface>
            <bounce/>
            <friction>
              <ode/>
            </friction>
            <contact>
              <ode/>
            </contact>
          </surface>
        </collision>
        <collision name='base_link_collision_right_axis'>
          <pose>0 -0.14 -0.02 -1.5708 0 0</pose>
          <geometry>
            <cylinder>
              <length>0.02</length>
              <radius>0.0025</radius>
            </cylinder>
          </geometry>
          <max_contacts>10</max_contacts>
          <surface>
            <bounce/>
            <friction>
              <ode/>
            </friction>
            <contact>
              <ode/>
            </contact>
          </surface>
        </collision>
        <visual name='base_link_visual_camera_link'>
          <pose>0 0 0.1 0 -0 0</pose>
          <geometry>
            <box>
              <size>0.02 0.08 0.05</size>
            </box>
          </geometry>
        </visual>
        <visual name='base_link_visual_chassis'>
          <pose>0 0 0 0 -0 0</pose>
          <geometry>
            <cylinder>
              <length>0.08</length>
              <radius>0.17</radius>
            </cylinder>
          </geometry>
          <material>
            <script>
              <name>Gazebo/Yellow</name>
              <uri>__default__</uri>
            </script>
          </material>
        </visual>
        <visual name='base_link_visual_hokuyo_laser_link'>
          <pose>0 0 0.06 0 -0 0</pose>
          <geometry>
            <cylinder>
              <length>0.04</length>
              <radius>0.045</radius>
            </cylinder>
          </geometry>
        </visual>
        <visual name='base_link_visual_imu_sensor_link'>
          <pose>-0.1 0 0.05 0 -0 0</pose>
          <geometry>
            <box>
              <size>0.02 0.02 0.02</size>
            </box>
          </geometry>
        </visual>
        <visual name='base_link_visual_left_axis'>
          <pose>0 0.14 -0.02 -1.5708 0 0</pose>
          <geometry>
            <cylinder>
              <length>0.02</length>
              <radius>0.0025</radius>
            </cylinder>
          </geometry>
        </visual>
        <visual name='base_link_visual_right_axis'>
          <pose>0 -0.14 -0.02 -1.5708 0 0</pose>
          <geometry>
            <cylinder>
              <length>0.02</length>
              <radius>0.0025</radius>
            </cylinder>
          </geometry>
        </visual>
        <velocity_decay>
          <linear>0</linear>
          <angular>0</angular>
        </velocity_decay>
        <velocity_decay>
          <linear>0</linear>
          <angular>0</angular>
        </velocity_decay>
        <velocity_decay>
          <linear>0</linear>
          <angular>0</angular>
        </velocity_decay>
        <sensor name='camera' type='camera'>
          <update_rate>30</update_rate>
          <camera name='head'>
            <horizontal_fov>1.39626</horizontal_fov>
            <image>
              <width>800</width>
              <height>600</height>
              <format>R8G8B8</format>
            </image>
            <clip>
              <near>0.02</near>
              <far>300</far>
            </clip>
            <noise>
              <type>gaussian</type>
              <mean>0</mean>
              <stddev>0.007</stddev>
            </noise>
          </camera>
          <plugin name='camera_controller' filename='libgazebo_ros_camera.so'>
            <alwaysOn>true</alwaysOn>
            <updateRate>0.0</updateRate>
            <cameraName>iRobot/camera</cameraName>
            <imageTopicName>image_raw</imageTopicName>
            <cameraInfoTopicName>camera_info</cameraInfoTopicName>
            <frameName>camera_link</frameName>
            <hackBaseline>0.07</hackBaseline>
            <distortionK1>0.0</distortionK1>
            <distortionK2>0.0</distortionK2>
            <distortionK3>0.0</distortionK3>
            <distortionT1>0.0</distortionT1>
            <distortionT2>0.0</distortionT2>
          </plugin>
          <pose>0 0 0.1 0 -0 0</pose>
        </sensor>
        <gravity>1</gravity>
        <velocity_decay>
          <linear>0</linear>
          <angular>0</angular>
        </velocity_decay>
        <gravity>1</gravity>
        <sensor name='head_hokuyo_sensor' type='ray'>
          <visualize>0</visualize>
          <update_rate>40</update_rate>
          <ray>
            <scan>
              <horizontal>
                <samples>360</samples>
                <resolution>1</resolution>
                <min_angle>-3.14159</min_angle>
                <max_angle>3.14159</max_angle>
              </horizontal>
            </scan>
            <range>
              <min>0.06</min>
              <max>40</max>
              <resolution>0.025</resolution>
            </range>
            <noise>
              <type>gaussian</type>
              <mean>0</mean>
              <stddev>0</stddev>
            </noise>
          </ray>
          <plugin name='gazebo_ros_head_hokuyo_controller' filename='libgazebo_ros_laser.so'>
            <robotNamespace/>
            <topicName>laser_scan</topicName>
            <frameName>hokuyo_laser_link</frameName>
          </plugin>
          <pose>0 0 0.06 0 -0 0</pose>
        </sensor>
        <gravity>1</gravity>
        <velocity_decay>
          <linear>0</linear>
          <angular>0</angular>
        </velocity_decay>
        <self_collide>0</self_collide>
        <gravity>1</gravity>
        <sensor name='imu_sensor' type='imu'>
          <always_on>1</always_on>
          <update_rate>1000</update_rate>
          <visualize>1</visualize>
          <topic>__default_topic__</topic>
          <plugin name='imu_plugin' filename='libgazebo_ros_imu_sensor.so'>
            <topicName>imu_data</topicName>
            <bodyName>imu_sensor_link</bodyName>
            <updateRateHZ>10.0</updateRateHZ>
            <gaussianNoise>0.0</gaussianNoise>
            <xyzOffset>0 0 0</xyzOffset>
            <rpyOffset>0 0 0</rpyOffset>
          </plugin>
          <pose>-0.1 0 0.05 0 -0 0</pose>
        </sensor>
        <kinematic>0</kinematic>
      </link>
      <link name='left_wheel_link'>
        <pose>0 0.14 -0.02 0 -0 0</pose>
        <inertial>
          <pose>0 0.01 0 -1.5708 0 0</pose>
          <mass>0.5</mass>
          <inertia>
            <ixx>0.00375</ixx>
            <ixy>0</ixy>
            <ixz>0</ixz>
            <iyy>0.00375</iyy>
            <iyz>0</iyz>
            <izz>0.00125</izz>
          </inertia>
        </inertial>
        <collision name='left_wheel_link_collision'>
          <pose>0 0 0 -1.5708 0 0</pose>
          <geometry>
            <cylinder>
              <length>0.02</length>
              <radius>0.03</radius>
            </cylinder>
          </geometry>
          <max_contacts>1</max_contacts>
          <surface>
            <contact>
              <ode>
                <kp>1e+07</kp>
                <kd>1</kd>
                <min_depth>0.0001</min_depth>
              </ode>
            </contact>
            <friction>
              <ode>
                <mu>50</mu>
                <mu2>10</mu2>
                <fdir1>1 0 0</fdir1>
              </ode>
            </friction>
            <bounce/>
          </surface>
        </collision>
        <visual name='left_wheel_link_visual'>
          <pose>0 0 0 -1.5708 0 0</pose>
          <geometry>
            <cylinder>
              <length>0.02</length>
              <radius>0.03</radius>
            </cylinder>
          </geometry>
          <material>
            <script>
              <name>Gazebo/Grey</name>
              <uri>__default__</uri>
            </script>
          </material>
        </visual>
        <gravity>1</gravity>
        <velocity_decay>
          <linear>0</linear>
          <angular>0</angular>
        </velocity_decay>
        <self_collide>0</self_collide>
        <gravity>1</gravity>
        <kinematic>0</kinematic>
      </link>
      <joint name='left_wheel_rot_joint' type='revolute'>
        <child>left_wheel_link</child>
        <parent>base_link</parent>
        <axis>
          <xyz>0 1 0</xyz>
          <limit>
            <lower>-1e+16</lower>
            <upper>1e+16</upper>
          </limit>
          <dynamics/>
        </axis>
      </joint>
      <link name='right_wheel_link'>
        <pose>0 -0.14 -0.02 0 -0 0</pose>
        <inertial>
          <pose>0 0.01 0 -1.5708 0 0</pose>
          <mass>0.5</mass>
          <inertia>
            <ixx>0.00375</ixx>
            <ixy>0</ixy>
            <ixz>0</ixz>
            <iyy>0.00375</iyy>
            <iyz>0</iyz>
            <izz>0.00125</izz>
          </inertia>
        </inertial>
        <collision name='right_wheel_link_collision'>
          <pose>0 0 0 -1.5708 0 0</pose>
          <geometry>
            <cylinder>
              <length>0.02</length>
              <radius>0.03</radius>
            </cylinder>
          </geometry>
          <max_contacts>1</max_contacts>
          <surface>
            <contact>
              <ode>
                <kp>1e+07</kp>
                <kd>1</kd>
                <min_depth>0.0001</min_depth>
              </ode>
            </contact>
            <friction>
              <ode>
                <mu>50</mu>
                <mu2>10</mu2>
                <fdir1>1 0 0</fdir1>
              </ode>
            </friction>
            <bounce/>
          </surface>
        </collision>
        <visual name='right_wheel_link_visual'>
          <pose>0 0 0 -1.5708 0 0</pose>
          <geometry>
            <cylinder>
              <length>0.02</length>
              <radius>0.03</radius>
            </cylinder>
          </geometry>
          <material>
            <script>
              <name>Gazebo/Grey</name>
              <uri>__default__</uri>
            </script>
          </material>
        </visual>
        <gravity>1</gravity>
        <velocity_decay>
          <linear>0</linear>
          <angular>0</angular>
        </velocity_decay>
        <self_collide>0</self_collide>
        <gravity>1</gravity>
        <kinematic>0</kinematic>
      </link>
      <joint name='right_wheel_rot_joint' type='revolute'>
        <child>right_wheel_link</child>
        <parent>base_link</parent>
        <axis>
          <xyz>0 1 0</xyz>
          <limit>
            <lower>-1e+16</lower>
            <upper>1e+16</upper>
          </limit>
          <dynamics/>
        </axis>
      </joint>
      <link name='sphere1'>
        <pose>0.14 0 -0.04 0 -0 0</pose>
        <inertial>
          <pose>0 0 0 0 -0 0</pose>
          <mass>0.3</mass>
          <inertia>
            <ixx>0.0012</ixx>
            <ixy>0</ixy>
            <ixz>0</ixz>
            <iyy>0.0012</iyy>
            <iyz>0</iyz>
            <izz>0.0012</izz>
          </inertia>
        </inertial>
        <collision name='sphere1_collision'>
          <pose>0 0 0 0 -0 0</pose>
          <geometry>
            <sphere>
              <radius>0.01</radius>
            </sphere>
          </geometry>
          <max_contacts>1</max_contacts>
          <surface>
            <contact>
              <ode>
                <kp>1e+07</kp>
                <kd>1</kd>
                <min_depth>0.0001</min_depth>
              </ode>
            </contact>
            <friction>
              <ode>
                <mu>0</mu>
                <mu2>0</mu2>
                <fdir1>1 0 0</fdir1>
              </ode>
            </friction>
            <bounce/>
          </surface>
        </collision>
        <visual name='sphere1_visual'>
          <pose>0 0 0 0 -0 0</pose>
          <geometry>
            <sphere>
              <radius>0.01</radius>
            </sphere>
          </geometry>
          <material>
            <script>
              <name>Gazebo/Grey</name>
              <uri>__default__</uri>
            </script>
          </material>
        </visual>
        <gravity>1</gravity>
        <velocity_decay>
          <linear>0</linear>
          <angular>0</angular>
        </velocity_decay>
        <self_collide>0</self_collide>
        <gravity>1</gravity>
        <kinematic>0</kinematic>
      </link>
      <joint name='sphere_joint1' type='revolute'>
        <child>sphere1</child>
        <parent>base_link</parent>
        <axis>
          <xyz>0 0 1</xyz>
          <limit>
            <lower>0</lower>
            <upper>0</upper>
            <effort>100</effort>
            <velocity>100</velocity>
          </limit>
          <dynamics/>
        </axis>
      </joint>
      <link name='sphere2'>
        <pose>-0.14 0 -0.04 0 -0 0</pose>
        <inertial>
          <pose>0 0 0 0 -0 0</pose>
          <mass>0.3</mass>
          <inertia>
            <ixx>0.0012</ixx>
            <ixy>0</ixy>
            <ixz>0</ixz>
            <iyy>0.0012</iyy>
            <iyz>0</iyz>
            <izz>0.0012</izz>
          </inertia>
        </inertial>
        <collision name='sphere2_collision'>
          <pose>0 0 0 0 -0 0</pose>
          <geometry>
            <sphere>
              <radius>0.01</radius>
            </sphere>
          </geometry>
          <max_contacts>1</max_contacts>
          <surface>
            <contact>
              <ode>
                <kp>1e+07</kp>
                <kd>1</kd>
                <min_depth>0.0001</min_depth>
              </ode>
            </contact>
            <friction>
              <ode>
                <mu>0</mu>
                <mu2>0</mu2>
                <fdir1>1 0 0</fdir1>
              </ode>
            </friction>
            <bounce/>
          </surface>
        </collision>
        <visual name='sphere2_visual'>
          <pose>0 0 0 0 -0 0</pose>
          <geometry>
            <sphere>
              <radius>0.01</radius>
            </sphere>
          </geometry>
          <material>
            <script>
              <name>Gazebo/Grey</name>
              <uri>__default__</uri>
            </script>
          </material>
        </visual>
        <gravity>1</gravity>
        <velocity_decay>
          <linear>0</linear>
          <angular>0</angular>
        </velocity_decay>
        <self_collide>0</self_collide>
        <gravity>1</gravity>
        <kinematic>0</kinematic>
      </link>
      <joint name='sphere_joint2' type='revolute'>
        <child>sphere2</child>
        <parent>base_link</parent>
        <axis>
          <xyz>0 0 1</xyz>
          <limit>
            <lower>0</lower>
            <upper>0</upper>
            <effort>100</effort>
            <velocity>100</velocity>
          </limit>
          <dynamics/>
        </axis>
      </joint>
      <static>0</static>
      <plugin name='differential_drive_controller' filename='libgazebo_ros_diff_drive.so'>
        <rosDebugLevel>Debug</rosDebugLevel>
        <publishWheelTF>false</publishWheelTF>
        <publishWheelJointState>true</publishWheelJointState>
        <alwaysOn>true</alwaysOn>
        <leftJoint>left_wheel_rot_joint</leftJoint>
        <rightJoint>right_wheel_rot_joint</rightJoint>
        <wheelSeparation>0.28</wheelSeparation>
        <wheelDiameter>0.06</wheelDiameter>
        <torque>20</torque>
        <wheelAcceleration>1.8</wheelAcceleration>
        <commandTopic>cmd_vel</commandTopic>
        <odometryTopic>odom</odometryTopic>
        <odometryFrame>odom</odometryFrame>
        <odometrySource>encoder</odometrySource>
        <robotBaseFrame>base_link</robotBaseFrame>
        <updateRate>10.0</updateRate>
      </plugin>
      <plugin name='joint_state_publisher' filename='libgazebo_ros_joint_state_publisher.so'>
        <jointName>left_wheel_rot_joint, right_wheel_rot_joint</jointName>
        <updateRate>10.0</updateRate>
        <alwaysOn>true</alwaysOn>
      </plugin>
      <plugin name='imu_plugin' filename='libgazebo_ros_imu.so'>
        <bodyName>base_link</bodyName>
        <updateRate>100.0</updateRate>
        <topicName>imu_data</topicName>
        <serviceName>imu_service</serviceName>
        <gaussianNoise>0.1</gaussianNoise>
        <xyzOffset>0 0 0</xyzOffset>
        <rpyOffset>0 0 0</rpyOffset>
      </plugin>
      <pose>1 -2 0 0 -0 0</pose>
    </model>
    <model name='my_model'>
      <pose>0 -1 0.1 0 -0 0</pose>
      <static>0</static>
      <link name='link'>
        <inertial>
          <mass>0.3</mass>
          <inertia>
            <ixx>0.00725</ixx>
            <ixy>0</ixy>
            <ixz>0</ixz>
            <iyy>0.00725</iyy>
            <iyz>0</iyz>
            <izz>0.0125</izz>
          </inertia>
        </inertial>
        <collision name='collision'>
          <geometry>
            <box>
              <size>0.5 0.5 0.2</size>
            </box>
          </geometry>
          <max_contacts>10</max_contacts>
          <surface>
            <bounce/>
            <friction>
              <ode/>
            </friction>
            <contact>
              <ode/>
            </contact>
          </surface>
        </collision>
        <visual name='visual'>
          <geometry>
            <box>
              <size>0.5 0.5 0.2</size>
            </box>
          </geometry>
          <material>
            <script>
              <uri>file://media/materials/scripts/gazebo.material</uri>
              <name>Gazebo/Wood</name>
            </script>
          </material>
        </visual>
        <velocity_decay>
          <linear>0</linear>
          <angular>0</angular>
        </velocity_decay>
        <self_collide>0</self_collide>
        <kinematic>0</kinematic>
        <gravity>1</gravity>
      </link>
    </model>
    <state world_name='default'>
      <sim_time>869 103000000</sim_time>
      <real_time>874 408348089</real_time>
      <wall_time>1452973203 200051171</wall_time>
      <model name='ground_plane'>
        <pose>0 0 0 0 -0 0</pose>
        <link name='link'>
          <pose>0 0 0 0 -0 0</pose>
          <velocity>0 0 0 0 -0 0</velocity>
          <acceleration>0 0 0 0 -0 0</acceleration>
          <wrench>0 0 0 0 -0 0</wrench>
        </link>
      </model>
      <model name='iRobot'>
        <pose>-0.999946 -1.99999 0.049897 1e-06 -8.07794e-28 2e-06</pose>
        <link name='base_link'>
          <pose>-0.999946 -1.99999 0.049897 1e-06 -8.07794e-28 2e-06</pose>
          <velocity>0 0 2.2e-05 -4e-06 0 0</velocity>
          <acceleration>0 0 0 0 -0 0</acceleration>
          <wrench>0 0 0 0 -0 0</wrench>
        </link>
        <link name='left_wheel_link'>
          <pose>-0.999946 -1.85999 0.029897 1e-06 0.000939 2e-06</pose>
          <velocity>0 0 2.1e-05 -4e-06 1.5e-05 -1.29247e-26</velocity>
          <acceleration>0 0 0 0 -0 0</acceleration>
          <wrench>0 0 0 0 -0 0</wrench>
        </link>
        <link name='right_wheel_link'>
          <pose>-0.999945 -2.13999 0.029897 1e-06 0.000955 2e-06</pose>
          <velocity>0 0 2.2e-05 -4e-06 1.5e-05 -1.29247e-26</velocity>
          <acceleration>0 0 0 0 -0 0</acceleration>
          <wrench>0 0 0 0 -0 0</wrench>
        </link>
        <link name='sphere1'>
          <pose>-0.859946 -1.99999 0.009897 1e-06 -8.07794e-28 2e-06</pose>
          <velocity>0 -0 2.3e-05 -4e-06 0 0</velocity>
          <acceleration>0 0 0 0 -0 0</acceleration>
          <wrench>0 0 0 0 -0 0</wrench>
        </link>
        <link name='sphere2'>
          <pose>-1.13995 -1.99999 0.009897 1e-06 -8.07794e-28 2e-06</pose>
          <velocity>0 -0 2.3e-05 -4e-06 -0 -5e-06</velocity>
          <acceleration>0 0 0 0 -0 0</acceleration>
          <wrench>0 0 0 0 -0 0</wrench>
        </link>
      </model>
      <model name='iRobot_0'>
        <pose>5.1e-05 -1.99999 0.049897 1e-06 -8.07794e-28 2e-06</pose>
        <link name='base_link'>
          <pose>5.1e-05 -1.99999 0.049897 1e-06 -8.07794e-28 2e-06</pose>
          <velocity>0 0 2.2e-05 -4e-06 0 0</velocity>
          <acceleration>0 0 0 0 -0 0</acceleration>
          <wrench>0 0 0 0 -0 0</wrench>
        </link>
        <link name='left_wheel_link'>
          <pose>5.1e-05 -1.85999 0.029897 1e-06 0.000849 2e-06</pose>
          <velocity>0 0 2.1e-05 -4e-06 1.5e-05 -1.29247e-26</velocity>
          <acceleration>0 0 0 0 -0 0</acceleration>
          <wrench>0 0 0 0 -0 0</wrench>
        </link>
        <link name='right_wheel_link'>
          <pose>5.2e-05 -2.13999 0.029897 1e-06 0.000863 2e-06</pose>
          <velocity>0 0 2.2e-05 -4e-06 1.5e-05 -1.29247e-26</velocity>
          <acceleration>0 0 0 0 -0 0</acceleration>
          <wrench>0 0 0 0 -0 0</wrench>
        </link>
        <link name='sphere1'>
          <pose>0.140051 -1.99999 0.009897 1e-06 -8.07794e-28 2e-06</pose>
          <velocity>0 -0 2.3e-05 -4e-06 0 0</velocity>
          <acceleration>0 0 0 0 -0 0</acceleration>
          <wrench>0 0 0 0 -0 0</wrench>
        </link>
        <link name='sphere2'>
          <pose>-0.139949 -1.99999 0.009897 1e-06 -8.07794e-28 2e-06</pose>
          <velocity>0 -0 2.3e-05 -4e-06 -0 6e-06</velocity>
          <acceleration>0 0 0 0 -0 0</acceleration>
          <wrench>0 0 0 0 -0 0</wrench>
        </link>
      </model>
      <model name='iRobot_1'>
        <pose>1.00005 -1.99999 0.049897 1e-06 -8.07794e-28 2e-06</pose>
        <link name='base_link'>
          <pose>1.00005 -1.99999 0.049897 1e-06 -8.07794e-28 2e-06</pose>
          <velocity>0 0 2.2e-05 -4e-06 0 0</velocity>
          <acceleration>0 0 0 0 -0 0</acceleration>
          <wrench>0 0 0 0 -0 0</wrench>
        </link>
        <link name='left_wheel_link'>
          <pose>1.00005 -1.85999 0.029897 1e-06 0.000765 2e-06</pose>
          <velocity>0 0 2.1e-05 -4e-06 1.5e-05 -1.29247e-26</velocity>
          <acceleration>0 0 0 0 -0 0</acceleration>
          <wrench>0 0 0 0 -0 0</wrench>
        </link>
        <link name='right_wheel_link'>
          <pose>1.00005 -2.13999 0.029897 1e-06 0.000778 2e-06</pose>
          <velocity>0 0 2.2e-05 -4e-06 1.5e-05 -1.29247e-26</velocity>
          <acceleration>0 0 0 0 -0 0</acceleration>
          <wrench>0 0 0 0 -0 0</wrench>
        </link>
        <link name='sphere1'>
          <pose>1.14005 -1.99999 0.009897 1e-06 -8.07794e-28 2e-06</pose>
          <velocity>0 -0 2.3e-05 -4e-06 0 0</velocity>
          <acceleration>0 0 0 0 -0 0</acceleration>
          <wrench>0 0 0 0 -0 0</wrench>
        </link>
        <link name='sphere2'>
          <pose>0.860049 -1.99999 0.009897 1e-06 -8.07794e-28 2e-06</pose>
          <velocity>0 -0 2.3e-05 -4e-06 -0 6e-06</velocity>
          <acceleration>0 0 0 0 -0 0</acceleration>
          <wrench>0 0 0 0 -0 0</wrench>
        </link>
      </model>
      <model name='my_model'>
        <pose>-0 -1 0.1 0 -0 0</pose>
        <link name='link'>
          <pose>-0 -1 0.1 0 -0 0</pose>
          <velocity>0 0 0 0 -0 0</velocity>
          <acceleration>0 0 0 0 -0 0</acceleration>
          <wrench>0 0 0 0 -0 0</wrench>
        </link>
      </model>
    </state>
    <gui fullscreen='0'>
      <camera name='user_camera'>
        <pose>5 -5 2 0 0.275643 2.35619</pose>
        <view_controller>orbit</view_controller>
      </camera>
    </gui>
  </world>
</sdf>
